Workbook

Sheet Payslip
A1: MONTHS | B1: 2020 | C1: 2021 | D1: C-B | N1: MONTHS | O1: 2021 | P1: 2022 | Q1: O-N
A2: JAN(QVA) | B2: 17909 | C2: 25792 | D2: =C2-B2 -> 7883 | N2: JAN(QVA) | O2: 25792 | P2: 32119 | Q2: =AVERAGE(P2-O2) -> 6327
A3: FEB | B3: 24142 | C3: 25243 | D3: =C3-B3 -> 1101 | N3: FEB | O3: 25243 | P3: 28869 | Q3: =P3-O3 -> 3626
A4: MAR | B4: 23804 | C4: 25243 | D4: =C4-B4 -> 1439 | N4: MAR | O4: 25243 | P4: 28869 | Q4: =P4-O4 -> 3626
A5: APR(QVA) | B5: 25983 | C5: 28197 | D5: =C5-B5 -> 2214 | N5: APR(QVA) | O5: 28197 | P5: 34319 | Q5: =P5-O5 -> 6122
A6: MAY | B6: 23206 | C6: 25243 | D6: =C6-B6 -> 2037 | N6: MAY | O6: 25243 | P6: 31638 | Q6: =P6-O6 -> 6395
A7: JUN | B7: 23206 | C7: 29311 | D7: =C7-B7 -> 6105 | N7: JUN | O7: 29311 | P7: 29994 | Q7: =P7-O7 -> 683
A8: JUL(QVA) | B8: 26894 | C8: 30828 | D8: =C8-B8 -> 3934 | N8: JUL(QVA) | O8: 30828 | P8: 36513 | Q8: =P8-O8 -> 5685
A9: AUG | B9: 23436 | C9: 25609 | D9: =C9-B9 -> 2173 | N9: AUG | O9: 25609 | P9: 29263 | Q9: =P9-O9 -> 3654
A10: SEP | B10: 24686 | C10: 26859 | D10: =C10-B10 -> 2173 | N10: SEP | O10: 26859 | P10: 30513 | Q10: =P10-O10 -> 3654
A11: OCT(QVA) | B11: 26486 | C11: 31359 | D11: =C11-B11 -> 4873 | N11: OCT(QVA) | O11: 31359 | P11: 36513 | Q11: =P11-O11 -> 5154
A12: NOV | B12: 24686 | C12: 26859 | D12: =C12-B12 -> 2173 | N12: NOV | O12: 26859 | P12: 30513 | Q12: =P12-O12 -> 3654
A13: DEC | B13: 24676 | C13: 26849 | D13: =C13-B13 -> 2173 | N13: DEC | O13: 26849 | P13: 30493 | Q13: =P13-O13 -> 3644
A14: Total Take Home | B14: =SUM(B2:B13) -> 289114 | C14: =SUM(C2:C13) -> 327392 | D14: =SUM(D2:D13) -> 38278 | N14: Total Take Home | O14: =SUM(O2:O13) -> 327392 | P14: =SUM(P2:P13) -> 379616 | Q14: =SUM(Q2:Q13) -> 52224
A15: CTC | B15: 336000 LPA | C15: 366000 LPA | D15: =AVERAGE(D2:D13) -> 3189.8333 | E15: <-Avg Increment | N15: CTC | O15: 366000 LPA | P15: 426000LPA | Q15: =AVERAGE(Q2:Q13) -> 4352 | R15: <-Avg Increment
C16: 395000 LPA | O16: 395000 LPA | P16: 450000 LPA
A17: Deduction | B17: 46000 | C17: 22500 | N17: Deduction | O17: 22500 | P17: 17800
C18: 32740 | O18: 32740 | P18: 44560
B19: 24k on Avg/month | C19: 27.2k on Avg/month | O19: 27.2k on Avg/month | P19: 31.6k on Avg/month
N20: QVA= ~4500
B21: Final Anniversary
B22: Band
F33: Min LPA= No. Of years Experience*1.5+1
F34: Max LPA= No. Of years Experience*3+1
A37: MONTHS | B37: 2022 | C37: 2023 | D37: C-B | N37: MONTHS | O37: 2023 | P37: 2024 | Q37: O-N
A38: JAN(QVA) | B38: 32119 | C38: 35263 | D38: =C38-B38 -> 3144 | E38: Prof. Tax | N38: JAN(QVA) | O38: 35263 | P38: =35232+46582 -> 81814 | Q38: =P38-O38 -> 46551 | R38: FFS from TCS= 46.5k
A39: FEB | B39: 28869 | C39: 30513 | D39: =C39-B39 -> 1644 | N39: FEB | O39: 30513 | P39: 53507 | Q39: =P39-O39 -> 22994
A40: MAR | B40: 28869 | C40: 33296 | D40: =C40-B40 -> 4427 | N40: MAR | O40: 33296 | P40: 51826 | Q40: =P40-O40 -> 18530
A41: APR(QVA) | B41: 34319 | C41: 38012 | D41: =C41-B41 -> 3693 | N41: APR | O41: 38012 | P41: 50778 | Q41: =P41-O41 -> 12766
A42: MAY | B42: 31638 | C42: 31374 | D42: =C42-B42 -> -264 | E42: Health Insurance | N42: MAY | O42: 31374 | P42: 54747 | Q42: =P42-O42 -> 23373
A43: JUN | B43: 29994 | C43: 31374 | D43: =C43-B43 -> 1380 | E43: Health Insurance | N43: JUN | O43: 31374 | P43: 54748 | Q43: =P43-O43 -> 23374
A44: JUL(QVA) | B44: 36513 | C44: 38562 | D44: =C44-B44 -> 2049 | N44: JUL | O44: 38562 | P44: 54747 | Q44: =P44-O44 -> 16185
A45: AUG | B45: 29263 | C45: 31012 | D45: =C45-B45 -> 1749 | E45: Prof. Tax | N45: AUG | O45: 31012 | P45: 54748 | Q45: =P45-O45 -> 23736
A46: SEP | B46: 30513 | C46: 32262 | D46: =C46-B46 -> 1749 | N46: SEP | O46: 32262 | P46: 54748 | Q46: =P46-O46 -> 22486
A47: OCT(QVA) | B47: 36513 | C47: 38562 | D47: =C47-B47 -> 2049 | N47: OCT | O47: 38562 | P47: 46102 | Q47: =P47-O47 -> 7540
A48: NOV | B48: 30513 | C48: 32262 | D48: =C48-B48 -> 1749 | N48: NOV | O48: 32262 | P48: 46776 | Q48: =P48-O48 -> 14514
A49: DEC | B49: 30493 | C49: 32242 | D49: =C49-B49 -> 1749 | N49: DEC | O49: 32242 | P49: 46775 | Q49: =P49-O49 -> 14533
A50: Total Take Home | B50: =SUM(B38:B49) -> 379616 | C50: =SUM(C38:C49) -> 404734 | D50: =SUM(D38:D49) -> 25118 | N50: Total Take Home | O50: =SUM(O38:O49) -> 404734 | P50: =SUM(P38:P49) -> 651316 | Q50: =SUM(Q38:Q49) -> 246582
A51: CTC | B51: 426000LPA | C51: 450000 LPA | D51: =AVERAGE(D38:D49) -> 2093.1667 | E51: <-Avg Increment | N51: CTC | O51: 450000 LPA | P51: 800000 | Q51: =AVERAGE(Q38:Q49) -> 20548.5
B52: 450000 LPA | C52: 480000 LPA | O52: 480000 LPA
...

Sheet Hike
A2: Year=20-21 | B2: Year=21-22 | C2: Year=22-23 | D2: Year=23-24 | E2: Year=24-25
A3: =Payslip!D2 -> 7883 | B3: =Payslip!Q2 -> 6327 | C3: =Payslip!D38 -> 3144 | D3: =Payslip!Q38 -> 46551 | E3: =Payslip!D62 -> -27119
A4: =Payslip!D3 -> 1101 | B4: =Payslip!Q3 -> 3626 | C4: =Payslip!D39 -> 1644 | D4: =Payslip!Q39 -> 22994 | E4: =Payslip!D63 -> 5874
A5: =Payslip!D4 -> 1439 | B5: =Payslip!Q4 -> 3626 | C5: =Payslip!D40 -> 4427 | D5: =Payslip!Q40 -> 18530 | E5: =Payslip!D64 -> 2262
A6: =Payslip!D5 -> 2214 | B6: =Payslip!Q5 -> 6122 | C6: =Payslip!D41 -> 3693 | D6: =Payslip!Q41 -> 12766 | E6: =Payslip!D65 -> 79753
A7: =Payslip!D6 -> 2037 | B7: =Payslip!Q6 -> 6395 | C7: =Payslip!D42 -> -264 | D7: =Payslip!Q42 -> 23373 | E7: =Payslip!D66 -> 25784
A8: =Payslip!D7 -> 6105 | B8: =Payslip!Q7 -> 683 | C8: =Payslip!D43 -> 1380 | D8: =Payslip!Q43 -> 23374 | E8: =Payslip!D67 -> 58063
A9: =Payslip!D8 -> 3934 | B9: =Payslip!Q8 -> 5685 | C9: =Payslip!D44 -> 2049 | D9: =Payslip!Q44 -> 16185 | E9: =Payslip!D68 -> 25784
A10: =Payslip!D9 -> 2173 | B10: =Payslip!Q9 -> 3654 | C10: =Payslip!D45 -> 1749 | D10: =Payslip!Q45 -> 23736 | E10: =Payslip!D69 -> 24533
A11: =Payslip!D10 -> 2173 | B11: =Payslip!Q10 -> 3654 | C11: =Payslip!D46 -> 1749 | D11: =Payslip!Q46 -> 22486 | E11: =Payslip!D70 -> 25783
A12: =Payslip!D11 -> 4873 | B12: =Payslip!Q11 -> 5154 | C12: =Payslip!D47 -> 2049 | D12: =Payslip!Q47 -> 7540 | E12: =Payslip!D71 -> 34429
A13: =Payslip!D12 -> 2173 | B13: =Payslip!Q12 -> 3654 | C13: =Payslip!D48 -> 1749 | D13: =Payslip!Q48 -> 14514 | E13: =Payslip!D72 -> 33755
A14: =Payslip!D13 -> 2173 | B14: =Payslip!Q13 -> 3644 | C14: =Payslip!D49 -> 1749 | D14: =Payslip!Q49 -> 14533 | E14: =Payslip!D73 -> -46775
... A16: =Payslip!D15 -> 3189.8333 | B16: =Payslip!Q15 -> 4352 | C16: =Payslip!D51 -> 2093.1667 | D16: =Payslip!Q51 -> 20548.5 | E16: =Payslip!D75 -> 20177.167

Sheet Investments
A1: Investments | B1: Amount | C1: Tenure | D1: Interest | E1: DOJ(MM/DD/YYYY) | F1: Maturity(MM/DD/YYYY) | G1: Notes
A2: SBI Savings(FD) | B2: 20000 | C2: Every month | D2: 2.5 | E2: 43831 | F2: NA | G2: NA
A3: PPF | B3: 5000 | C3: 15years | D3: 7.1 | E3: 45143 | F3: 50861 | G3: NA
A4: PLI Endowment(10L) | B4: 4500 | C4: 18years (Maturity Age -45) | D4: 936000 (Total Bonus) | E4: 45345 | F4: 51920 | G4: 27- Age at the time of starting . Maturity 1936000
A5: Insurance SBI (upto 2L) | B5: 284 | C5: Every Year | D5: NA | E5: NA | F5: NA | G5: NA
A6: Post Office (RD) | B6: 7000 | C6: 5 years | D6: 6.7 | E6: 45988 | F6: 47814 | G6: Invest - 4.2L , Interest - 79.5k - Maturity - 499564
A7: SBI RD | B7: 5000 | C7: 2 years | D7: 6.45 | E7: 45988 | F7: 46718 | G7: Invest - 1.2L , Interest - 8.3k - Maturity - 128358
A8: Gold Scheme | B8: NA | C8: NA | D8: NA | E8: NA | F8: NA | G8: NA
A9: SIP | B9: NA | C9: NA | D9: NA | E9: NA | F9: NA | G9: NA
A11: Approx: Monthly Deposit | B11: 42k | C11: (Investment)

Sheet PLI
A1: PLI Endowment Assurance (Santosh) Overview * Type: Life insurance + savings. * Sum Assured: ₹10,00,000. * Entry Age: 27 years. * Maturity Age: 45 years → Policy Term = 18 years. * Premium: ₹4,500 (likely monthly as per your input). * Bonus Rate: ₹52 per ₹1,000 sum assured per year (current declared rate for FY 2025-26). * Terminal Bonus: ₹20 per ₹10,000 sum assured (max ₹1,000) for policies ≥20 years. Since your term is 18 years, terminal bonus does NOT apply. Bonus Calculation Formula: {Bonus} = {Sum Assured} * { {Bonus Rate}/{1000} }* {Policy Term} {Bonus} = 10,00,000 * {{52}/{1000}} * 18 = ₹9,36,000 Maturity Amount {Maturity Value} = {Sum Assured} + {Total Bonus} {Maturity Value} = ₹10,00,000 + ₹9,36,000 = ₹19,36,000
A2: Total Premium Paid If ₹4,500 is monthly: {Total Premium} = ₹4,500 * 12 * 18 = ₹9,72,000 Effective Returns {Net Gain} = ₹19,36,000 - ₹9,72,000 = ₹9,64,000
